import test

var t = test.t

t.scope(__file__)

t.interpret("Verify catch of custom exception.",
    """
    class Error(code: Integer, message: String) < Exception(message)    {
        public var @code = code
    }

    try: {
        raise Error(100, "Test")
    except Error as e:
        if e.code != 100: {
            raise Exception("Failed.")
        }
    }
    """)

t.interpret("Verify catch in another function.",
    """
    define g
    {
        try: {
            raise ValueError("")
        except Exception:
            1
        }
    }

    define f
    {
        var a = 1, b = 2, c = 3
        g()
    }

    f()
    """)

t.interpret("Verify exception passing through a foreign call.",
    """
    define f(a: Integer) : Integer
    {
        raise ValueError("")
    }

    for i in 0...5: {
        var v = [1, 2, 3]
        try: {
            v.map(f)
        except Exception:

        }
    }
    """)

t.interpret("Verify getting the message of an exception var.",
    """
    try: {
        1 / 0
    except Exception as e:
        var v = e.message
    }
    """)

t.interpret("Verify that exception traceback is created and usable.",
    """
    try: {
        raise ValueError("")
    except ValueError as e:
        var v = e.traceback[0].split(":")[-1]
    }
    """)

t.interpret("Verify all branches of a try block are tried.",
    """
    # This test make sure that all branches of a try+except are being tried,
    # and not just the first one.

    try: {
        1 / 0
    except IndexError:
        0
    except ValueError:
        0
    except DivisionByZeroError:
        0
    }
    """)

t.interpret("Verify native raise and catch, called from a foreign function.",
    """
    define f(a: Integer) : Integer
    {
        try: {
            if a % 2: {
                raise ValueError("")
            }
        except Exception:

        }

        return a
    }


    [1, 2, 3, 4].map(f)
    """)

t.interpret("Repeatedly try and catch inside of a loop.",
    """
    define f {
        var a = 1, b = 1, c = 1, d = 1
        var e = 1, g = 1, h = 1
        raise ValueError("")
    }

    var i = 10

    while i < 100: {
        try: {
            f()
        except Exception:
            0
        }

        i += 1
    }
    """)

t.interpret("Verify contents of an exception raised by vm.",
    """
    define h {
        0 % 0
    }

    define g {
        var v = ["1", "a", "3", "-4"]
        var w = v.map(String.parse_i)
        var x = w.select(Option.is_some)
        var y = x.map(Option.unwrap)
        h()
    }

    define f {
        var v = 10
        var w = v + v
        g()
    }

    try: {
        f()
    except DivisionByZeroError as e:
        if e.message != "Attempt to divide by zero.": {
            raise Exception("Exception message is incorrect.")
        }

        var expected_trace =
        ["test\/[subinterp]:21: in __main__",
         "test\/[subinterp]:17: in f",
         "test\/[subinterp]:11: in g",
         "test\/[subinterp]:3: in h"]

        if e.traceback != expected_trace: {
            print("trace given is \\n" ++ e.traceback.join("\\n"))
            print("trace expected is \\n" ++ expected_trace.join("\\n"))
            raise Exception("Traceback is incorrect.")
        }
    }
    """)

t.interpret("Verify contents of a raised exception.",
    """
    define h {
        raise RuntimeError("This is the message.")
    }

    define g {
        var v = ["1", "a", "3", "-4"]
        var w = v.map(String.parse_i)
        var x = w.select(Option.is_some)
        var y = x.map(Option.unwrap)
        h()
    }

    define f {
        var v = 10
        var w = v + v
        g()
    }

    try: {
        f()
    except RuntimeError as e:
        if e.message != "This is the message.": {
            raise Exception("Exception message is incorrect.")
        }

        var expected_trace =
        ["test\/[subinterp]:21: in __main__",
         "test\/[subinterp]:17: in f",
         "test\/[subinterp]:11: in g",
         "test\/[subinterp]:3: in h"]

        if e.traceback != expected_trace: {
            raise Exception("Traceback is incorrect.")
        }
    }
    """)

t.interpret("Construct and raise all exceptions.",
    """
    var ok = true

    try: {
        var v = DivisionByZeroError("DivisionByZeroError")
        raise(v)
    except DivisionByZeroError as e:
        if e.message != "DivisionByZeroError" ||
           e.traceback.size() != 1: {
            ok = false
        }
    }
    try: {
        var v = Exception("Exception")
        raise(v)
    except Exception as e:
        if e.message != "Exception" ||
           e.traceback.size() != 1: {
            ok = false
        }
    }
    try: {
        var v = IndexError("IndexError")
        raise(v)
    except IndexError as e:
        if e.message != "IndexError" ||
           e.traceback.size() != 1: {
            ok = false
        }
    }
    try: {
        var v = IOError("IOError")
        raise(v)
    except IOError as e:
        if e.message != "IOError" ||
           e.traceback.size() != 1: {
            ok = false
        }
    }
    try: {
        var v = KeyError("KeyError")
        raise(v)
    except KeyError as e:
        if e.message != "KeyError" ||
           e.traceback.size() != 1: {
            ok = false
        }
    }
    try: {
        var v = RuntimeError("RuntimeError")
        raise(v)
    except RuntimeError as e:
        if e.message != "RuntimeError" ||
           e.traceback.size() != 1: {
            ok = false
        }
    }
    try: {
        var v = ValueError("ValueError")
        raise(v)
    except ValueError as e:
        if e.message != "ValueError" ||
           e.traceback.size() != 1: {
            ok = false
        }
    }

    if ok == false: {
        raise Exception("Failed.")
    }
    """)

t.interpret("Verify format of calltrace and exceptions.",
    """
    define f {
        var error_line = 0
        var trace_line = __line__ + 1
        var last_trace_line = calltrace()[-1]
        var last_error_line = ""

        try: {
            error_line = __line__ + 1
            0/0
        except DivisionByZeroError as e:
            last_error_line = e.traceback[-1]
        }

        var template = "{0}:{1}: in {2}"
        var expect_error_line = template.format(__file__, error_line, __function__)
        var expect_trace_line = template.format(__file__, trace_line, __function__)

        if last_trace_line != expect_trace_line ||
           last_error_line != expect_error_line: {
           raise Exception("Failed.")
        }
    }

    f()
    """)
